<?xml version="1.0" ?>
<robot name="turtlebot3_burger" xmlns:xacro="http://ros.org/wiki/xacro">

  <xacro:arg name="namespace" default=""/>
  <xacro:property name="namespace" value="$(arg namespace)"/>

  <material name="black">
    <color rgba="0.0 0.0 0.0 1.0"/>
  </material>

  <material name="dark">
    <color rgba="0.3 0.3 0.3 1.0"/>
  </material>

  <material name="light_black">
    <color rgba="0.4 0.4 0.4 1.0"/>
  </material>

  <material name="blue">
    <color rgba="0.0 0.0 0.8 1.0"/>
  </material>

  <material name="green">
    <color rgba="0.0 0.8 0.0 1.0"/>
  </material>

  <material name="grey">
    <color rgba="0.5 0.5 0.5 1.0"/>
  </material>

  <material name="orange">
    <color rgba="1.0 0.4235 0.0392 1.0"/>
  </material>

  <material name="brown">
    <color rgba="0.8706 0.8118 0.7647 1.0"/>
  </material>

  <material name="red">
    <color rgba="0.8 0.0 0.0 1.0"/>
  </material>

  <material name="white">
    <color rgba="1.0 1.0 1.0 1.0"/>
  </material>

  <link name="${namespace}base_footprint"/>

  <joint name="${namespace}base_joint" type="fixed">
    <parent link="${namespace}base_footprint"/>
    <child link="${namespace}base_link"/>
    <origin xyz="0.0 0.0 0.010" rpy="0 0 0"/>
  </joint>

  <link name="${namespace}base_link">
    <visual>
      <origin xyz="-0.032 0 0.0" rpy="0 0 0"/>
      <geometry>
        <mesh filename="file://$(find llm_description)/turtlebot/bases/burger_base.stl" scale="0.001 0.001 0.001"/>
      </geometry>
      <material name="light_black"/>
    </visual>

    <collision>
      <origin xyz="-0.032 0 0.070" rpy="0 0 0"/>
      <geometry>
        <box size="0.140 0.140 0.143"/>
      </geometry>
    </collision>

    <inertial>
      <origin xyz="0 0 0" rpy="0 0 0"/>
      <mass value="8.2573504e-01"/>
      <inertia ixx="2.2124416e-03" ixy="-1.2294101e-05" ixz="3.4938785e-05" 
               iyy="2.1193702e-03" iyz="-5.0120904e-06" izz="2.0064271e-03" />
    </inertial>
  </link>

  <joint name="${namespace}wheel_left_joint" type="continuous">
    <parent link="${namespace}base_link"/>
    <child link="${namespace}wheel_left_link"/>
    <origin xyz="0.0 0.08 0.023" rpy="-1.57 0 0"/>
    <axis xyz="0 0 1"/>
  </joint>

  <link name="${namespace}wheel_left_link">
    <visual>
      <origin xyz="0 0 0" rpy="1.57 0 0"/>
      <geometry>
        <mesh filename="file://$(find llm_description)/turtlebot/wheels/left_tire.stl" scale="0.001 0.001 0.001"/>
      </geometry>
      <material name="dark"/>
    </visual>

    <collision>
      <origin xyz="0 0 0" rpy="0 0 0"/>
      <geometry>
        <cylinder length="0.018" radius="0.033"/>
      </geometry>
    </collision>

    <inertial>
      <origin xyz="0 0 0" />
      <mass value="2.8498940e-02" />
      <inertia ixx="1.1175580e-05" ixy="-4.2369783e-11" ixz="-5.9381719e-09" 
               iyy="1.1192413e-05" iyz="-1.4400107e-11" izz="2.0712558e-05" />
    </inertial>
  </link>

  <joint name="${namespace}wheel_right_joint" type="continuous">
    <parent link="${namespace}base_link"/>
    <child link="${namespace}wheel_right_link"/>
    <origin xyz="0.0 -0.080 0.023" rpy="-1.57 0 0"/>
    <axis xyz="0 0 1"/>
  </joint>

  <link name="${namespace}wheel_right_link">
    <visual>
      <origin xyz="0 0 0" rpy="1.57 0 0"/>
      <geometry>
        <mesh filename="file://$(find llm_description)/turtlebot/wheels/right_tire.stl" scale="0.001 0.001 0.001"/>
      </geometry>
      <material name="dark"/>
    </visual>

    <collision>
      <origin xyz="0 0 0" rpy="0 0 0"/>
      <geometry>
        <cylinder length="0.018" radius="0.033"/>
      </geometry>
    </collision>

    <inertial>
      <origin xyz="0 0 0" />
      <mass value="2.8498940e-02" />
      <inertia ixx="1.1175580e-05" ixy="-4.2369783e-11" ixz="-5.9381719e-09" 
               iyy="1.1192413e-05" iyz="-1.4400107e-11" izz="2.0712558e-05" />
    </inertial>
  </link>

  <joint name="${namespace}caster_back_joint" type="fixed">
    <parent link="${namespace}base_link"/>
    <child link="${namespace}caster_back_link"/>
    <origin xyz="-0.081 0 -0.004" rpy="-1.57 0 0"/>
  </joint>

  <link name="${namespace}caster_back_link">
    <collision>
      <origin xyz="0 0.001 0" rpy="0 0 0"/>
      <geometry>
        <box size="0.030 0.009 0.020"/>
      </geometry>
    </collision>

    <inertial>
      <origin xyz="0 0 0" />
      <mass value="0.005" />
      <inertia ixx="0.001" ixy="0.0" ixz="0.0" 
               iyy="0.001" iyz="0.0" izz="0.001" />
    </inertial>
  </link>

  <joint name="${namespace}imu_joint" type="fixed">
    <parent link="${namespace}base_link"/>
    <child link="${namespace}imu_link"/>
    <origin xyz="-0.032 0 0.068" rpy="0 0 0"/>
  </joint>

  <link name="${namespace}imu_link"/>

  <joint name="${namespace}scan_joint" type="fixed">
    <parent link="${namespace}base_link"/>
    <child link="${namespace}base_scan"/>
    <origin xyz="-0.032 0 0.172" rpy="0 0 0"/>
  </joint>

  <link name="${namespace}base_scan">
    <visual>
      <origin xyz="0 0 0.0" rpy="0 0 0"/>
      <geometry>
        <mesh filename="file://$(find llm_description)/turtlebot/sensors/lds.stl" scale="0.001 0.001 0.001"/>
      </geometry>
      <material name="dark"/>
    </visual>

    <collision>
      <origin xyz="0.015 0 -0.0065" rpy="0 0 0"/>
      <geometry>
        <cylinder length="0.0315" radius="0.055"/>
      </geometry>
    </collision>

    <inertial>
      <mass value="0.114" />
      <origin xyz="0 0 0" />
      <inertia ixx="0.001" ixy="0.0" ixz="0.0" 
               iyy="0.001" iyz="0.0" izz="0.001" />
    </inertial>
  </link>

  <link
    name="camera_link">
    <inertial>
      <origin
        xyz="0 0 0"  
        rpy="0 0 0" />
      <mass
        value="0.0037785110963087" />
      <inertia
        ixx="0.00041109010827315"
        ixy="2.00243497326135E-05"
        ixz="1.48233721450063E-07"
        iyy="4.97776083745444E-05"
        iyz="1.08586163834263E-08"
        izz="0.000432963162718765" />
    </inertial>
    <visual>
      <origin
        xyz="0 0 0"
        rpy="0 0 0" />
      <geometry>
        <mesh
          filename="file://$(find llm_description)/meshes/d435.dae" />
      </geometry>
      <material
        name="">
        <color
          rgba="0.752941176470588 0.752941176470588 0.752941176470588 1" />
      </material>
    </visual>
    <!-- <collision>
      <origin
        xyz="0 0 0"
        rpy="0 0 0" />
      <geometry>
        <mesh
          filename="file://$(find llm_description)/meshes/d435.dae" />
      </geometry>
    </collision> -->
  </link>

  <joint
    name="camera_joint"
    type="fixed">
    <origin
      xyz="0.032 0 0.142"
      rpy="0 -0.38 0" /> <!-- Rotate 180 degrees around Z to face forward -->
    <parent
      link="base_link" />
    <child
      link="camera_link" />
    <axis
      xyz="0 0 0" />
  </joint>

  <link name="camera_optical_frame">
    <inertial>
      <mass value="0.001" />
      <inertia ixx="0.00001" ixy="0" ixz="0" iyy="0.00001" iyz="0" izz="0.00001" />
    </inertial>
  </link>

  <joint name="camera_optical_joint" type="fixed">
    <parent link="camera_link"/>
    <child link="camera_optical_frame"/>
    <!-- change here as you adjust camera -->
    <axis xyz="0 0 1"/>
    <origin xyz="0 0 0" rpy="0 0 0"/> <!-- "0 0.58 0" -->
  </joint>


  <gazebo reference="camera_optical_frame">
      <sensor name="realsense2_camera" type="rgbd_camera">
        <ignition_frame_id>camera_optical_frame</ignition_frame_id>
        <camera name="realsense2_camera">
          <horizontal_fov>1.2043</horizontal_fov>
          <lens>
            <intrinsics>
              <fx>915.3003540039062</fx>
              <fy>914.0320434570312</fy>
              <cx>642.724365234375</cx>
              <cy>361.9780578613281</cy>
              <s>0</s>
            </intrinsics>
          </lens>
          <distortion>
            <k1>0.0</k1>
            <k2>0.0</k2>
            <k3>0.0</k3>
            <p1>0.0</p1>
            <p2>0.0</p2>
            <center>0.5 0.5</center>
          </distortion>
          <image>
            <width>1280</width>
            <height>720</height>
            <format>R8G8B8</format>
          </image>
          <clip>
            <near>0.1</near>
            <far>100</far>
          </clip>
          <depth_camera>
            <clip>
              <near>0.1</near>
              <far>100</far>
            </clip>
          </depth_camera>
          <noise>
            <type>gaussian</type>
            <mean>0.0</mean>
            <stddev>0.007</stddev>
          </noise>
        </camera>
        <always_on>1</always_on>
        <update_rate>4</update_rate>
        <visualize>0</visualize>
        <topic>camera</topic>
      </sensor>

  </gazebo>

  <gazebo reference="${namespace}base_scan">
    <sensor name="laser" type="gpu_lidar">
      <always_on>true</always_on>
      <visualize>false</visualize>
      <topic>scan</topic>
      <pose>0 0 0 0 0 0</pose>
      <update_rate>10</update_rate>
      <gz_frame_id>${namespace}base_scan</gz_frame_id>
      <lidar>
        <scan>
          <horizontal>
            <samples>360</samples>
            <resolution>1.0</resolution>
            <min_angle>-3.14</min_angle>
            <max_angle>3.14</max_angle>
          </horizontal>
          <vertical>
            <samples>1</samples>
            <resolution>0.01</resolution>
            <min_angle>0</min_angle>
            <max_angle>0</max_angle>
          </vertical>
        </scan>
        <range>
          <min>0.2</min>
          <max>8.0</max>
          <resolution>0.02</resolution>
        </range>
        <noise>
          <type>gaussian</type>
          <mean>0.0</mean>
          <stddev>0.01</stddev>
        </noise>
      </lidar>
    </sensor>
  </gazebo>

  <gazebo>
    <plugin filename="ignition-gazebo-diff-drive-system" name="ignition::gazebo::systems::DiffDrive">
      <left_joint>${namespace}wheel_left_joint</left_joint>
      <right_joint>${namespace}wheel_right_joint</right_joint>
      <wheel_separation>0.16</wheel_separation>
      <wheel_radius>0.033</wheel_radius>
      <max_acceleration>1.0</max_acceleration>
      <max_linear_velocity>0.5</max_linear_velocity>
      <min_linear_velocity>-0.5</min_linear_velocity>
      <max_angular_velocity>1.0</max_angular_velocity>
      <min_angular_velocity>-1.0</min_angular_velocity>
      <topic>cmd_vel</topic>
      <frame_id>odom</frame_id>
      <child_frame_id>${namespace}base_footprint</child_frame_id>
    </plugin>
  </gazebo>

  <gazebo>
    <plugin filename="ignition-gazebo-odometry-publisher-system" name="ignition::gazebo::systems::OdometryPublisher">
      <odom_topic>odom</odom_topic>
      <odom_frame>odom</odom_frame>
      <tf_topic>tf</tf_topic>
      <robot_base_frame>${namespace}base_footprint</robot_base_frame>
    </plugin>
  </gazebo>

  <gazebo>
    <plugin filename="ignition-gazebo-joint-state-publisher-system" name="ignition::gazebo::systems::JointStatePublisher">
      <topic>joint_states</topic>
      <joint_name>${namespace}wheel_left_joint</joint_name>
      <joint_name>${namespace}wheel_right_joint</joint_name>
    </plugin>
  </gazebo>

</robot>